Workbook

Sheet About
B3: This template was created by the people of ICT Institute
B5: You can find the latest version and other templates here:
B6: https://ictinstitute.nl/free-templates/
B8: You can use this template freely under the Create Commons Attribution license
B9: https://creativecommons.org/licenses/by/4.0/
B11: You can do the following with the templates:
B13: Share. You can share the templates and any documents made with these templates freely, with any one that you want to share it with.
B14: Adapt. You can make new documents based on the templates, make changes, add elements or delete elements as much as you want. You can even do this in commercial organisations of for commercial purposes.
B16: If you are a customer, you do not have to mention ICT Institute anywhere
B17: If you are not a customer, you must keep the text "create by the people of ICT Institute" somewhere
B19: Note that the use of these templates is of course at your own risk.
B20: Note also that the ISO standards are copyrighted. You must buy the standard from NEN or ISO before using it
... B25: https://ictinstitute.nl/iso27002-2022-explained-1/

Sheet 1. issues
A1: Internal and external issues | B1: Category (internal / external)
A2: Growth plans | B2: Internal
A3: Internal improvement projects | B3: Internal
A4: … | B4: …
A5: The increased interest in information security and privacy in society. Since the introduction of the GDPR in 2018, everyone is much more aware of privacy risks. The risk of reputational damage has increased due to the increased interest | B5: External
A6: Increase in digitization and working from home. This has increased the chance of success with phishing and digital attacks, for example. | B6: External
A7: An increase in organized cybercrime in society. Think, for example, of ransomware attacks, which are carried out because of the apparently positive financial returns. | B7: External
A8: … | B8: …

Sheet 2. stakeholder analysis
A1: Stakeholder analysis
A2: Version: | B2: 0.1
A3: Document owner: | B3: CEO
A4: Date (last update): | B4: 44927
A5: Classification: | B5: internal use
A7: Stakeholder | B7: Interest level of stakeholder | C7: Specific requirements addressed via the ISMS | D7: Communication with stakeholder
D8: Information security policy, continuously, via website | E8: Information security procedures and internal training | F8: Other communication steps (what, how, when)
A9: Internal stakeholders
A10: Shareholders | B10: Very high | C10: Protecting Company Information. Compliance with laws and regulations (compliance). Comply with common industry standards. | D10: x | F10: Updates on status in shareholder meeting
A11: Employees and applicants | B11: Very high | C11: Protection of personal data (contact details, salary details). Full compliance with all legal rules. Clear instructions on how to act yourself. Points of contact for questions | E11: x
A12: Platform user | B12: Very high | C12: Protection of personal data. Full compliance with all legal rules. Points of contact for questions | D12: x
A13: Board of Directors | B13: High | C13: Meeting legal requirements and societal expectations about data protection. Insight into risks, control over policy. | D13: x
A14: Works Council (OR) | B14: High | C14: Compliance with legal requirements, protection of personnel data, Involvement and insight into policy | D14: x | F14: Important changes will be submitted in advance.
A15: Information security team | B15: Very high | C15: Be informed of events, incidents, changes in the organisation and results of audits and measurements | D15: x | E15: x | F15: Recurring "informaiton security meeting". See annual calendar for frequency
A16: …
A17: …
A18: External Stakeholders
A19: Suppliers, including freelancers | B19: High | C19: Protection of personal data and other sensitive data. Reliable information and financial processes. Protection of personal data if the supplier is a self-employed person. | D19: x | F19: Appropriate agreements are made for each supplier to set expectations. Non-salaried staff has access to the same information as other staff. If necessary, procedures are shared with them
A20: Insurers and chain partners | B20: High | C20: Meeting legal requirements and social expectations. Reliable information and financial processes | D20: x | F20: Appropriate agreements are made for each partner to set expectations.
A21: Interest groups and client organizations | B21: Medium | C21: Meeting legal requirements and social expectations about data protection | D21: x
A22: Authority for Personal Data | B22: High | C22: Demonstrable compliance with GDPR | F22: The DPO maintains contact with the AP
A23: Other governments | B23: Medium | C23: Meeting legal requirements and societal expectations about data protection | D23: x
A24: Press and Media | B24: Low | C24: Meeting legal requirements and societal expectations about data protection, Be kept informed of publicly known incidents | D24: x
A25: accountant | B25: High | C25: Comply with legal requirements and ensure continuity | D25: x | F25: The accountant can request additional information if needed for thei financial process
A27: …
A28: …
A29: …
A35: Labels used:
B37: Category | C37: Definition
B38: Very high | C38: It is essential for the organization to meet the requirements and expectations of this data subject, and the stakeholder attaches great importance to information security.
B39: High | C39: It is important for the organization to meet the requirements and expectations of this data subject, and the data subject has an interest in information security. This also includes representatives of key stakeholders.
B40: Medium | C40: It is valuable for the organization to meet the requirements and expectations of this data subject, and the data subject has an interest in information security.
B41: Low | C41: No requirements have been agreed and the stakeholder has no concrete expectations. Stakeholder notices little of any incidents or deviations and is not immediately dissatisfied

Sheet Assets
B1: Information Asset Inventory
B2: For explanation of categories, see below
A3: nr. | B3: Name | C3: Description | D3: Owner | E3: relevant CIA aspects | F3: Is this personal data? | G3: Who should have access | H3: Category
A4: 1 | B4: Dashboard1 | C4: Dashboard with weekly reports for the finance department | D4: CFO | E4: CIA | F4: no | G4: All developer roles | H4: Data
A5: 2 | B5: CRM system | C5: System from salesforce with data of all retail customers | D5: Sales | E5: CI | F5: yes | G5: Sales managers | H5: Third parties
A6: 3 | B6: Dashboard1 source code | C6: Report scripts for creating dashboard1 | D6: CFO | E6: CIA | F6: no | G6: Developers | H6: Software
A7: 4 | B7: Confluence | C7: Documentation on Confluence | D7: CTO | E7: CI | F7: yes | G7: Own access management | H7: Organisation
A8: 5 | B8: User data | C8: User uploads | E8: .
A9: 6 | B9: Web Apps | C9: Web applications | E9: .
A10: 7 | B10: Websites | C10: Public websites | E10: .
A11: 8 | B11: Laptops | C11: Laptops of employees | E11: .
A12: 9 | B12: Servers | C12: Servers (in the cloud, mostly AWS) | E12: .
A13: 10 | B13: Phones | C13: Mobile phones | E13: .
A14: 11 | B14: HR | C14: HR files | E14: .
A15: 12 | B15: Finance | C15: Finance and accounting | E15: .
A16: 13 | B16: Bank account | C16: Bank account of company | E16: .
A17: 14 | B17: Documentation | C17: Slack / Wiki / Confluence | E17: .
A18: 15 | B18: Logs | C18: Log files (access log, error log) | E18: .
A19: 16 | B19: Headquarters | C19: Main office room | E19: .
A20: 17 | B20: Cloud storage | C20: Dropbox / Drive / Onedrive | E20: .
A21: 18 | E21: .
A22: 19 | E22: .
A23: 20 | E23: .
A24: 21 | E24: .
A25: 22 | E25: .
A26: 23 | E26: .
A27: 24 | E27: .
A28: 25 | E28: .
A29: 26 | E29: .
A30: 27 | E30: .
A31: 28 | E31: .
A32: 29 | E32: .
... A53: 50 | E53: .
B57: Category | C57: Description | F57: Class values | G57: Class values
B58: People | C58: Information accessible to one person or linked to unique role | F58: CIA | G58: yes
B59: Equipment | C59: Information inside or generated on/by specific devices | F59: CI | G59: no
B60: Environment | C60: Information linked to factors outside the company, e.g. city, region | F60: AI | G60: .
B61: Software | C61: Information stored by single IT systems | F61: none
B62: Data | C62: Structured information not linked to one software system | F62: .
B63: Organisation | C63: Any information about the organisation, e.g. org structure, processes
...

Sheet Risks and controls
B1: Risks and controls 2023
B2: Version: 0.1
B3: Date (last update): 01/01/2023
B4: Classification: internal use
B5: *CIA = Confidentiality, Integrity, Availability | G5: With current measures/controls | N5: After additional measures/controls
A6: Nr. | B6: Event | C6: CIA* | D6: Source of risk | E6: Applicable SoA controls/measures | F6: Additional measures taken | G6: Probability | H6: Impact | I6: Risk score | J6: Treatment decision (Accept, Reduce) | K6: Risk Treatment Plan in 2023 | L6: Risk owner name | M6: Date of risk owner approval | N6: Probability | O6: Impact | P6: Risk score
A7: 1 | B7: Breach of information protection law or legislation | C7: CIA | D7: Risk session 01-01-2023 | E7: 5.5, 5.31, 5.34, 8.10, 8.11 | F7: … | G7: Medium | H7: High | I7: =VLOOKUP(G7,$I$44:$M$48,5,FALSE)*VLOOKUP(H7,$I$44:$M$48,5,FALSE) -> 6 | J7: Reduce | K7: … | L7: John Wick | M7: 44927 | N7: Medium | O7: Low | P7: =VLOOKUP(N7,$I$44:$M$48,5,FALSE)*VLOOKUP(O7,$I$44:$M$48,5,FALSE) -> 2
A8: 2 | B8: Breach of contractual information protection obligation | C8: CIA | D8: Risk session 01-01-2023 | E8: 5.31 | F8: … | G8: Medium | H8: High | I8: =VLOOKUP(G8,$I$44:$M$48,5,FALSE)*VLOOKUP(H8,$I$44:$M$48,5,FALSE) -> 6 | J8: Reduce | K8: … | L8: John Wick | M8: 44927 | N8: Medium | O8: Low | P8: =VLOOKUP(N8,$I$44:$M$48,5,FALSE)*VLOOKUP(O8,$I$44:$M$48,5,FALSE) -> 2
A9: 3 | B9: Loss of assets by employees | C9: CIA | D9: Risk session 01-01-2023 | E9: 5.9, 5.10, 8.1, | F9: … | G9: Medium | H9: High | I9: =VLOOKUP(G9,$I$44:$M$48,5,FALSE)*VLOOKUP(H9,$I$44:$M$48,5,FALSE) -> 6 | J9: Reduce | K9: … | L9: John Wick | M9: 44927 | N9: Medium | O9: Low | P9: =VLOOKUP(N9,$I$44:$M$48,5,FALSE)*VLOOKUP(O9,$I$44:$M$48,5,FALSE) -> 2
A10: 4 | B10: Inproper handling of information assets by employees | C10: CIA | D10: Risk session 01-01-2023 | E10: 5.36, 5.37, 6.7, 7.13, 7.14 | F10: … | G10: Medium | H10: High | I10: =VLOOKUP(G10,$I$44:$M$48,5,FALSE)*VLOOKUP(H10,$I$44:$M$48,5,FALSE) -> 6 | J10: Reduce | K10: … | L10: John Wick | M10: 44927 | N10: Medium | O10: Low | P10: =VLOOKUP(N10,$I$44:$M$48,5,FALSE)*VLOOKUP(O10,$I$44:$M$48,5,FALSE) -> 2
A11: 5 | B11: CIA of information compromised by employee by accident | C11: CIA | D11: Risk session 01-01-2023 | E11: 6.2, 6.3 | F11: … | G11: Medium | H11: High | I11: =VLOOKUP(G11,$I$44:$M$48,5,FALSE)*VLOOKUP(H11,$I$44:$M$48,5,FALSE) -> 6 | J11: Reduce | K11: … | L11: John Wick | M11: 44927 | N11: Medium | O11: Low | P11: =VLOOKUP(N11,$I$44:$M$48,5,FALSE)*VLOOKUP(O11,$I$44:$M$48,5,FALSE) -> 2
A12: 6 | B12: CIA of information compromised by (ex) employee on purpose | C12: CIA | D12: Risk session 01-01-2023 | E12: 6.1, 6.2, 6.4, 6.5, 6.6, 8.12 | F12: … | G12: Medium | H12: High | I12: =VLOOKUP(G12,$I$44:$M$48,5,FALSE)*VLOOKUP(H12,$I$44:$M$48,5,FALSE) -> 6 | J12: Reduce | K12: … | L12: John Wick | M12: 44927 | N12: Medium | O12: Low | P12: =VLOOKUP(N12,$I$44:$M$48,5,FALSE)*VLOOKUP(O12,$I$44:$M$48,5,FALSE) -> 2
A13: 7 | B13: Information compromised due to physical access to assets | C13: CIA | D13: Risk session 01-01-2023 | E13: 7.1, 7.2, 7.3, 7.4, 7.6, 7.7, 7.8, 7.9, 7.10 | F13: … | G13: Medium | H13: High | I13: =VLOOKUP(G13,$I$44:$M$48,5,FALSE)*VLOOKUP(H13,$I$44:$M$48,5,FALSE) -> 6 | J13: Reduce | K13: … | L13: John Wick | M13: 44927 | N13: Medium | O13: Low | P13: =VLOOKUP(N13,$I$44:$M$48,5,FALSE)*VLOOKUP(O13,$I$44:$M$48,5,FALSE) -> 2
A14: 8 | B14: Malware on internal systems | C14: CIA | D14: Risk session 01-01-2023 | E14: 8.7, 8.18 | F14: … | G14: Medium | H14: High | I14: =VLOOKUP(G14,$I$44:$M$48,5,FALSE)*VLOOKUP(H14,$I$44:$M$48,5,FALSE) -> 6 | J14: Reduce | K14: … | L14: John Wick | M14: 44927 | N14: Medium | O14: Low | P14: =VLOOKUP(N14,$I$44:$M$48,5,FALSE)*VLOOKUP(O14,$I$44:$M$48,5,FALSE) -> 2
A15: 9 | B15: Unauthorized access to internal networking | C15: CI | D15: Risk session 01-01-2023 | E15: 8.20, 8.21, 8.22 | F15: … | G15: Medium | H15: High | I15: =VLOOKUP(G15,$I$44:$M$48,5,FALSE)*VLOOKUP(H15,$I$44:$M$48,5,FALSE) -> 6 | J15: Reduce | K15: … | L15: John Wick | M15: 44927 | N15: Medium | O15: Low | P15: =VLOOKUP(N15,$I$44:$M$48,5,FALSE)*VLOOKUP(O15,$I$44:$M$48,5,FALSE) -> 2
A16: 10 | B16: CIA of source code is compromised | C16: CIA | D16: Risk session 01-01-2023 | E16: 8.4, | F16: … | G16: Medium | H16: High | I16: =VLOOKUP(G16,$I$44:$M$48,5,FALSE)*VLOOKUP(H16,$I$44:$M$48,5,FALSE) -> 6 | J16: Reduce | K16: … | L16: John Wick | M16: 44927 | N16: Medium | O16: Low | P16: =VLOOKUP(N16,$I$44:$M$48,5,FALSE)*VLOOKUP(O16,$I$44:$M$48,5,FALSE) -> 2
A17: 11 | B17: Misconfiguration of IT system leads to vulnerability | C17: CI | D17: Risk session 01-01-2023 | E17: 8.9, 8.19 | F17: … | G17: Medium | H17: High | I17: =VLOOKUP(G17,$I$44:$M$48,5,FALSE)*VLOOKUP(H17,$I$44:$M$48,5,FALSE) -> 6 | J17: Reduce | K17: … | L17: John Wick | M17: 44927 | N17: Medium | O17: Low | P17: =VLOOKUP(N17,$I$44:$M$48,5,FALSE)*VLOOKUP(O17,$I$44:$M$48,5,FALSE) -> 2
A18: 12 | B18: Unauthorized access to information by personnel | C18: CI | D18: Risk session 01-01-2023 | E18: 5.12, 5.13, 5.15, 5.16, 5.17, 5.18, 8.3, 8.5 | F18: … | G18: Medium | H18: High | I18: =VLOOKUP(G18,$I$44:$M$48,5,FALSE)*VLOOKUP(H18,$I$44:$M$48,5,FALSE) -> 6 | J18: Reduce | K18: … | L18: John Wick | M18: 44927 | N18: Medium | O18: Low | P18: =VLOOKUP(N18,$I$44:$M$48,5,FALSE)*VLOOKUP(O18,$I$44:$M$48,5,FALSE) -> 2
A19: 13 | B19: Unpatched system or server is exploited | C19: CIA | D19: Risk session 01-01-2023 | E19: 5.7, 8.8 | F19: … | G19: Medium | H19: High | I19: =VLOOKUP(G19,$I$44:$M$48,5,FALSE)*VLOOKUP(H19,$I$44:$M$48,5,FALSE) -> 6 | J19: Reduce | K19: … | L19: John Wick | M19: 44927 | N19: Medium | O19: Low | P19: =VLOOKUP(N19,$I$44:$M$48,5,FALSE)*VLOOKUP(O19,$I$44:$M$48,5,FALSE) -> 2
A20: 14 | B20: Significant incident disrupts all operational systems | C20: IA | D20: Risk session 01-01-2023 | E20: 5.29, 5.30, 7.5, 7.11, 8.13, 8.14 | F20: … | G20: Medium | H20: High | I20: =VLOOKUP(G20,$I$44:$M$48,5,FALSE)*VLOOKUP(H20,$I$44:$M$48,5,FALSE) -> 6 | J20: Reduce | K20: … | L20: John Wick | M20: 44927 | N20: Medium | O20: Low | P20: =VLOOKUP(N20,$I$44:$M$48,5,FALSE)*VLOOKUP(O20,$I$44:$M$48,5,FALSE) -> 2
A21: 15 | B21: Unsafe supplier used as entry point for hack | C21: CIA | D21: Risk session 01-01-2023 | E21: 5.19, 5.20, 5.21, 5.22 | F21: … | G21: Medium | H21: High | I21: =VLOOKUP(G21,$I$44:$M$48,5,FALSE)*VLOOKUP(H21,$I$44:$M$48,5,FALSE) -> 6 | J21: Reduce | K21: … | L21: John Wick | M21: 44927 | N21: Medium | O21: Low | P21: =VLOOKUP(N21,$I$44:$M$48,5,FALSE)*VLOOKUP(O21,$I$44:$M$48,5,FALSE) -> 2
A22: 16 | B22: The company is fined for non-compliance with GDPR | C22: CIA | D22: Risk session 01-01-2023 | E22: 5.34 | F22: … | G22: Medium | H22: High | I22: =VLOOKUP(G22,$I$44:$M$48,5,FALSE)*VLOOKUP(H22,$I$44:$M$48,5,FALSE) -> 6 | J22: Reduce | K22: … | L22: John Wick | M22: 44927 | N22: Medium | O22: Low | P22: =VLOOKUP(N22,$I$44:$M$48,5,FALSE)*VLOOKUP(O22,$I$44:$M$48,5,FALSE) -> 2
A23: 17 | B23: Theft of Intellectual property | C23: CA | D23: Risk session 01-01-2023 | E23: 5.32, | F23: … | G23: Medium | H23: High | I23: =VLOOKUP(G23,$I$44:$M$48,5,FALSE)*VLOOKUP(H23,$I$44:$M$48,5,FALSE) -> 6 | J23: Reduce | K23: … | L23: John Wick | M23: 44927 | N23: Medium | O23: Low | P23: =VLOOKUP(N23,$I$44:$M$48,5,FALSE)*VLOOKUP(O23,$I$44:$M$48,5,FALSE) -> 2
A24: 18 | B24: Inproper response to incident leads to incident escalation | C24: CIA | D24: Risk session 01-01-2023 | E24: 5.24, 5.25, 5.26, 6.8, 8.15, 8.16 | F24: … | G24: Medium | H24: High | I24: =VLOOKUP(G24,$I$44:$M$48,5,FALSE)*VLOOKUP(H24,$I$44:$M$48,5,FALSE) -> 6 | J24: Reduce | K24: … | L24: John Wick | M24: 44927 | N24: Medium | O24: Low | P24: =VLOOKUP(N24,$I$44:$M$48,5,FALSE)*VLOOKUP(O24,$I$44:$M$48,5,FALSE) -> 2
A25: 19 | B25: Evidence of hack cannot be used in court | C25: CIA | D25: Risk session 01-01-2023 | E25: 5.28, 5.33, 8.15, 8.17 | F25: … | G25: Medium | H25: High | I25: =VLOOKUP(G25,$I$44:$M$48,5,FALSE)*VLOOKUP(H25,$I$44:$M$48,5,FALSE) -> 6 | J25: Reduce | K25: … | L25: John Wick | M25: 44927 | N25: Medium | O25: Low | P25: =VLOOKUP(N25,$I$44:$M$48,5,FALSE)*VLOOKUP(O25,$I$44:$M$48,5,FALSE) -> 2
A26: 20 | B26: Unintentional coding or architecture error leads to vulnerability | C26: CI | D26: Risk session 01-01-2023 | E26: 5.35, 8.25, 8.27, 8.28, 8.29, 8.33 | F26: … | G26: Medium | H26: High | I26: =VLOOKUP(G26,$I$44:$M$48,5,FALSE)*VLOOKUP(H26,$I$44:$M$48,5,FALSE) -> 6 | J26: Reduce | K26: … | L26: John Wick | M26: 44927 | N26: Medium | O26: Low | P26: =VLOOKUP(N26,$I$44:$M$48,5,FALSE)*VLOOKUP(O26,$I$44:$M$48,5,FALSE) -> 2
A27: 21 | B27: Incident takes place for the second time | C27: CIA | D27: Risk session 01-01-2023 | E27: 5.27, | F27: … | G27: Medium | H27: High | I27: =VLOOKUP(G27,$I$44:$M$48,5,FALSE)*VLOOKUP(H27,$I$44:$M$48,5,FALSE) -> 6 | J27: Reduce | K27: … | L27: John Wick | M27: 44927 | N27: Medium | O27: Low | P27: =VLOOKUP(N27,$I$44:$M$48,5,FALSE)*VLOOKUP(O27,$I$44:$M$48,5,FALSE) -> 2
A28: 22 | B28: InfoSec staff is not aware of new threats | C28: CIA | D28: Risk session 01-01-2023 | E28: 5.6, | F28: … | G28: Medium | H28: High | I28: =VLOOKUP(G28,$I$44:$M$48,5,FALSE)*VLOOKUP(H28,$I$44:$M$48,5,FALSE) -> 6 | J28: Reduce | K28: … | L28: John Wick | M28: 44927 | N28: Medium | O28: Low | P28: =VLOOKUP(N28,$I$44:$M$48,5,FALSE)*VLOOKUP(O28,$I$44:$M$48,5,FALSE) -> 2
A29: 23 | B29: Information lost after employee leaves | C29: A | D29: Risk session 01-01-2023 | E29: 5.11, | F29: … | G29: Medium | H29: High | I29: =VLOOKUP(G29,$I$44:$M$48,5,FALSE)*VLOOKUP(H29,$I$44:$M$48,5,FALSE) -> 6 | J29: Reduce | K29: … | L29: John Wick | M29: 44927 | N29: Medium | O29: Low | P29: =VLOOKUP(N29,$I$44:$M$48,5,FALSE)*VLOOKUP(O29,$I$44:$M$48,5,FALSE) -> 2
A30: 24 | B30: Change to infrastructure or configuration leads to new vulnerability | C30: CI | D30: Risk session 01-01-2023 | E30: 5.8, 8.32 | F30: … | G30: Medium | H30: High | I30: =VLOOKUP(G30,$I$44:$M$48,5,FALSE)*VLOOKUP(H30,$I$44:$M$48,5,FALSE) -> 6 | J30: Reduce | K30: … | L30: John Wick | M30: 44927 | N30: Medium | O30: Low | P30: =VLOOKUP(N30,$I$44:$M$48,5,FALSE)*VLOOKUP(O30,$I$44:$M$48,5,FALSE) -> 2
A31: 25 | B31: Audits or inspections disturb operations | C31: IA | D31: Risk session 01-01-2023 | E31: 8.34, | F31: … | G31: Medium | H31: High | I31: =VLOOKUP(G31,$I$44:$M$48,5,FALSE)*VLOOKUP(H31,$I$44:$M$48,5,FALSE) -> 6 | J31: Reduce | K31: … | L31: John Wick | M31: 44927 | N31: Medium | O31: Low | P31: =VLOOKUP(N31,$I$44:$M$48,5,FALSE)*VLOOKUP(O31,$I$44:$M$48,5,FALSE) -> 2
A32: 26 | B32: Accidental changes to production environment | C32: IA | D32: Risk session 01-01-2023 | E32: 8.31, | F32: … | G32: Medium | H32: High | I32: =VLOOKUP(G32,$I$44:$M$48,5,FALSE)*VLOOKUP(H32,$I$44:$M$48,5,FALSE) -> 6 | J32: Reduce | K32: … | L32: John Wick | M32: 44927 | N32: Medium | O32: Low | P32: =VLOOKUP(N32,$I$44:$M$48,5,FALSE)*VLOOKUP(O32,$I$44:$M$48,5,FALSE) -> 2
A33: 27 | B33: Software developed by third party contains vulnerability | C33: CI | D33: Risk session 01-01-2023 | E33: 8.26, 8.30, | F33: … | G33: Medium | H33: High | I33: =VLOOKUP(G33,$I$44:$M$48,5,FALSE)*VLOOKUP(H33,$I$44:$M$48,5,FALSE) -> 6 | J33: Reduce | K33: … | L33: John Wick | M33: 44927 | N33: Medium | O33: Low | P33: =VLOOKUP(N33,$I$44:$M$48,5,FALSE)*VLOOKUP(O33,$I$44:$M$48,5,FALSE) -> 2
A34: 28 | B34: Employee visits known malware website | C34: CI | D34: Risk session 01-01-2023 | E34: 8.23, | F34: … | G34: Medium | H34: High | I34: =VLOOKUP(G34,$I$44:$M$48,5,FALSE)*VLOOKUP(H34,$I$44:$M$48,5,FALSE) -> 6 | J34: Reduce | K34: … | L34: John Wick | M34: 44927 | N34: Medium | O34: Low | P34: =VLOOKUP(N34,$I$44:$M$48,5,FALSE)*VLOOKUP(O34,$I$44:$M$48,5,FALSE) -> 2
... A40: 34 | B40: Ransomware attack by hacktivist | C40: CI | D40: Context analys (chapter 4.1) | E40: n/a | F40: None | G40: Low | H40: High | I40: =VLOOKUP(G40,$I$44:$M$48,5,FALSE)*VLOOKUP(H40,$I$44:$M$48,5,FALSE) -> 3 | J40: Accept | K40: n/a | L40: John Wick | M40: 44934 | N40: Low | O40: High | P40: =VLOOKUP(N40,$I$44:$M$48,5,FALSE)*VLOOKUP(O40,$I$44:$M$48,5,FALSE) -> 3
I43: Category | J43: Probability / year | K43: Impact | M43: Score
I44: High | J44: >30% | K44: > € 100.000, or lives/organization in danger | M44: 3
I45: Medium | J45: >10% | K45: > € 10.000, primary process disturbed for >8h | M45: 2
I46: Low | J46: <10% | K46: < € 10.000, secundary process disturbed | M46: 1
I47: . | M47: 0
...

Sheet Mapping risks to SoA
B1: This tab helps you check whether you have taken all SoA controls into consideration during your risk assessments
B4: ISO 27001 control | C4: Time in risks
A5: 5.1 | B5: Policies for information security | C5: =COUNTIF('Risks and controls'!$E$7:$E$39,"*"&A5&"*")+COUNTIF('Risks and controls'!$E$7:$E$39,A5) -> 6
A6: 5.2 | B6: Information security roles and responsibilities | C6: =COUNTIF('Risks and controls'!$E$7:$E$39,"*"&A6&"*")+COUNTIF('Risks and controls'!$E$7:$E$39,A6) -> 7
A7: 5.3 | B7: Segregation of duties | C7: =COUNTIF('Risks and controls'!$E$7:$E$39,"*"&A7&"*")+COUNTIF('Risks and controls'!$E$7:$E$39,A7) -> 7
A8: 5.4 | B8: Management responsibilities | C8: =COUNTIF('Risks and controls'!$E$7:$E$39,"*"&A8&"*")+COUNTIF('Risks and controls'!$E$7:$E$39,A8) -> 1
A9: 5.5 | B9: Contact with authorities | C9: =COUNTIF('Risks and controls'!$E$7:$E$39,"*"&A9&"*")+COUNTIF('Risks and controls'!$E$7:$E$39,A9) -> 1
A10: 5.6 | B10: Contact with special interest groups | C10: =COUNTIF('Risks and controls'!$E$7:$E$39,"*"&A10&"*")+COUNTIF('Risks and controls'!$E$7:$E$39,A10) -> 1
A11: 5.7 | B11: Threat intelligence | C11: =COUNTIF('Risks and controls'!$E$7:$E$39,"*"&A11&"*")+COUNTIF('Risks and controls'!$E$7:$E$39,A11) -> 1
A12: 5.8 | B12: Information security in project management | C12: =COUNTIF('Risks and controls'!$E$7:$E$39,"*"&A12&"*")+COUNTIF('Risks and controls'!$E$7:$E$39,A12) -> 1
A13: 5.9 | B13: Inventory of information and other associated assets | C13: =COUNTIF('Risks and controls'!$E$7:$E$39,"*"&A13&"*")+COUNTIF('Risks and controls'!$E$7:$E$39,A13) -> 1
A14: 5.10 | B14: Acceptable use of information and other associated assets | C14: =COUNTIF('Risks and controls'!$E$7:$E$39,"*"&A14&"*")+COUNTIF('Risks and controls'!$E$7:$E$39,A14) -> 1
A15: 5.11 | B15: Return of assets | C15: =COUNTIF('Risks and controls'!$E$7:$E$39,"*"&A15&"*")+COUNTIF('Risks and controls'!$E$7:$E$39,A15) -> 1
A16: 5.12 | B16: Classification of information | C16: =COUNTIF('Risks and controls'!$E$7:$E$39,"*"&A16&"*")+COUNTIF('Risks and controls'!$E$7:$E$39,A16) -> 1
... A97: 8.34 | B97: Protection of information systems during audit testing | C97: =COUNTIF('Risks and controls'!$E$7:$E$39,"*"&A97&"*")+COUNTIF('Risks and controls'!$E$7:$E$39,A97) -> 1

Sheet ISO 27001 SoA
A1: Statement of Applicability ISO 27001:2022 | D1: Template by ICT Institute
A2: Organisation:
A3: Version: | B3: 44835 | I3: do not print this part
A4: Approval status: | B4: To be approved in management review
I5: For internal use (don’t share)
A6: Nr. | B6: Chapter | C6: Topic | D6: Control | E6: Applicable to our organisation | F6: Justification for inclusion | G6: Motivation for non-applicability | H6: Implemented in our organisation | I6: How and where implemented | J6: Control owner
E7: (Yes/No) | H7: (Yes/No)
A8: 5.1 | B8: Organizational controls | C8: Policies for information security | D8: Information security policy and topic-specific policies shall be defined, approved by management, published, communicated to and acknowledged by relevant personnel and relevant interested parties, and reviewed at planned intervals and if significant changes occur.
A9: 5.2 | B9: Organizational controls | C9: Information security roles and responsibilities | D9: Information security roles and responsibilities shall be defined and allocated according to the organization needs.
A10: 5.3 | B10: Organizational controls | C10: Segregation of duties | D10: Conflicting duties and conflicting areas of responsibility shall be segregated.
A11: 5.4 | B11: Organizational controls | C11: Management responsibilities | D11: Management shall require all personnel to apply information security in accordance with the established information security policy, top_x0002_ic-specific policies and procedures of the organization.
A12: 5.5 | B12: Organizational controls | C12: Contact with authorities | D12: The organization shall establish and maintain contact with relevant authorities.
A13: 5.6 | B13: Organizational controls | C13: Contact with special interest groups | D13: The organization shall establish and maintain contact with special interest groups or other specialist security forums and professional associations.
A14: 5.7 | B14: Organizational controls | C14: Threat intelligence | D14: Information relating to information security threats shall be collected and analysed to produce threat intelligence.
A15: 5.8 | B15: Organizational controls | C15: Information security in project management | D15: Information security shall be integrated into project management.
A16: 5.9 | B16: Organizational controls | C16: Inventory of information and other associated assets | D16: An inventory of information and other associated assets, including owners, shall be developed and maintained.
A17: 5.10 | B17: Organizational controls | C17: Acceptable use of information and other associated assets | D17: Rules for the acceptable use and procedures for handling information and other associated assets shall be identified, documented and implemented.
A18: 5.11 | B18: Organizational controls | C18: Return of assets | D18: Personnel and other interested parties as appropriate shall return all the organization’s assets in their possession upon change or termination of their employment, contract or agreement.
A19: 5.12 | B19: Organizational controls | C19: Classification of information | D19: Information shall be classified according to the information security needs of the organization based on confidentiality, integrity, availability and relevant interested party requirements.
... A100: 8.34 | B100: Technological controls | C100: Protection of information systems during audit testing | D100: Audit tests and other assurance activities involving assessment of operational systems shall be planned and agreed between the tester and appropriate management.

Sheet Explanation
B1: ISO 27001:2022 chapter | C1: This template
B2: 4.1 Understanding the organization and its context The organization shall determine external and internal issues that are relevant to its purpose and that affect its ability to achieve the intended outcome(s) of its information security management system. | C2: Internal and external issues
B3: 4.2 Understanding the needs and expectations of interested parties The organization shall determine:
B4: a) interested parties that are relevant to the information security management system; | C4: Stakeholder analysis column A
B5: b) the relevant requirements of these interested parties; | C5: Stakeholder analysis column C
B6: c) which of these requirements will be addressed through the information security management system | C6: Stakeholder analysis column C
B7: 7.4 Communication The organization shall determine the need for internal and external communications relevant to the information security management system including:
B8: a) on what to communicate; | C8: Stakeholder analysis columns D E F
B9: b) when to communicate; | C9: Stakeholder analysis columns D E F
B10: c) with whom to communicate; | C10: Stakeholder analysis columns D E F
B11: d) how to communicate. | C11: Stakeholder analysis columns D E F
A20: Category | B20: Definition
A21: Internal stakeholder | B21: Internal persons, groups, teams, roles, departments, etc. impacted by our protection of information
A22: External stakeholder | B22: External parties with a stake in our protection of information e.g. clients, authorities, subsidiaries, holdings, etc.
