Workbook

Sheet Over dit document
B4: Dit template is gemaakt door de mensen van ICT Institute.
B5: Het template mag gratis worden gebruikt, onder een creative commons licentie
B6: https://creativecommons.org/licenses/by/4.0/
B8: De nieuwste versie staat op:
B9: https://softwarezaken.nl/2022/01/gratis-27001-avg-templates/
B11: Je mag het template uitbreiden, aanpassen en bewerken zoveel je wilt
B12: Je mag het template en documenten gemaakt met het template doorgeven en delen zoveel je wilt
B14: Als je het template doorgeeft, dan moet je "gemaakt door de mensen van ICT Institute" laten staan
B16: Als je een document maakt met dit template en je bent geen opdrachtgever van ons, zet dat "gemaakt met template van ICT Institute" ergens in het document
B17: Als je een opdrachtgever bent van ICT Institute, dan mag je alles doen met dit template wat je wilt
B19: Let op dat je de ISO 27001 norm moet kopen bij NEN of een andere organisatie voordat je de norm gaat gebruiken. De norm is auteursrechtelijk beschermd
B21: Lees vooral ook deze artikelen als je aan de slag gaat:
... B26: https://ictinstitute.nl/risk-management-method/

Sheet 1. Issues
A1: Externe en interne belangrijke punten ('issues') | B1: Soort onderwerp (intern / extern) | C1: Toegevoegd op
A2: geplande overnames om dienstverlening uit te breiden | B2: Intern | C2: 45776
A3: De wens om IT-landschap moderner en robuuster te maken, bijv door netwerkverbeteringen | B3: Intern
A4: vragen van opdrachtgevers over NIS2 en bedrijfscontinuiteit en de wens om hieraan te voldoen | B4: Extern
A5: Voortduren van digitalisering en thuiswerken. Hierdoor is bijvoorbeeld de kans op succes bij phishing en op digitale aanvallen toegenomen. | B5: Extern
A6: Een toename in de samenleving van georganiseerde cybercriminaliteit. Denk hierbij bijvoorbeeld aan ransomware-aanvallen, die uitgevoerd worden vanwege de blijkbaar positieve financiële opbrengsten. | B6: Extern

Sheet 2. Belanghebbendenanalyse
A1: Belanghebbendenanalyse
A2: Versie: | B2: 0.1
A3: Documenteigenaar: | B3: CEO
A4: Datum (laatste aanpassing): | B4: 45870
A5: Classificatie: | B5: Intern gebruik
A7: Stakeholder / Indeling | B7: Belang stakeholder | C7: Specifieke eisen | D7: Specifieke verwachtingen | E7: Hoe wordt met stakeholder gecommuniceerd
A8: Interne belanghebbenden | E8: Beleid op externe website | F8: Procedures en communicatie op interne website | G8: Overige opmerkingen
A9: Aandeelhouders | B9: Zeer hoog | C9: Beschermen van bedrijfsinformatie | D9: Naleving van wet- en regelgeving (compliance). Voldoen aan gangbare normen in de industrie. | E9: x | G9: Rapportage in aandeelhoudersvergadering
A10: Medewerkers en sollicitanten | B10: Zeer hoog | C10: Bescherming van persoonsgegevens (contactgegevens, salarisgegevens) | D10: Volledige naleving van alle wettelijke regels. Duidelijke instructies hoe men zelf moet handelen. Aanspreekpunten bij vragen | E10: x | F10: x
A11: Gebruiker van het platform | B11: Zeer Hoog | C11: Bescherming van persoonsgegevens | D11: Volledige naleving van alle wettelijke regels. Aanspreekpunten bij vragen | E11: x
A12: Raad van Bestuur (deze regel weghalen indien niet aanwezig) | B12: Hoog | C12: Voldoen aan wettelijke eisen en maatschappelijke verwachtingen over bescherming gegegens | D12: Inzicht in risico's, controle over beleid. | E12: x | G12: Belangrijke wijzigingen worden vooraf voorgelegd en door RvB goedgekeurd. Directiebeoordeling
A13: Raad van Toezicht (deze regel weghalen indien niet aanwezig) | B13: Hoog | C13: Voldoen aan wettelijke eisen en maatschappelijke verwachtingen over bescherming gegegens | D13: Inzicht in risico's, controle over beleid. | E13: x | G13: Worden geïnformeerd door de raad van bestuur
A14: Ondernemingsraad (OR) (deze regel weghalen indien niet aanwezig) | B14: Hoog | C14: Voldoen aan wettelijke eisen, bescherming personeelsgegevens | D14: Betrokkenheid en inzicht in beleid | E14: x | F14: x | G14: Belangrijke wijzigingen worden vooraf voorgelegd.
A15: Medewerkers aan het ISMS | B15: Zeer hoog | C15: Tijdig bespreken veranderingen, incidenten, doelen, metrieken en afwijkingen | D15: Goed laten lopen van ISMS-processen | F15: x | G15: Overlegstructuur met verschillende meetings (team-overleg, bespreking met management, directiebeoordeling). De overlegmomenten en te bespreken punten staan in jaarplanning
A20: Externe belanghebbenden
A21: Leveranciers, inclusief ZZP-ers | B21: Hoog | C21: Bescherming van persoonsgegevens en andere gevoelige data. Betrouwbare informatie en financiële processen | D21: Bescherming persoonsgegevens indien de leverancier een ZZP-er is. | E21: x | G21: Per leverancier worden passende afspraken gemaakt om verwachtingen vast te leggen. Personeel niet in loondienst heeft toegang tot zelfde informatie als ander personeel. Indien nodig worden procedures met hen gedeeld
A22: Verzekeraars en ketenpartners | B22: Hoog | C22: Voldoen aan wettelijke eisen en maatschappelijke verwachtingen. Betrouwbare informatie en financiële processen | E22: x | G22: Per partner worden passende afspraken gemaakt om verwachtingen vast te leggen.
A23: Belangengroeperingen en clientenorganisaties | B23: Matig | C23: Voldoen aan wettelijke eisen en maatschappelijke verwachtingen over bescherming gegevens | E23: x
A24: Autoriteit Persoonsgegevens | B24: Hoog | C24: Aantoonbaar voldoen aan AVG | E24: x | G24: De FG onderhoudt contact met de AP
A25: Overige overheden | B25: Matig | C25: Voldoen aan wettelijke eisen en maatschappelijke verwachtingen over bescherming gegevens | E25: x
A26: Pers en Media | B26: Laag | C26: Voldoen aan wettelijke eisen en maatschappelijke verwachtingen over bescherming gegevens | D26: Op de hoogte gehouden worden bij publiek bekende incidenten | E26: x | G26: De afdeling communicatie onderhoudt contacten met pers en media
A27: Accountant | B27: Hoog | C27: Voldoen aan wettelijke eisen en zorgdragen voor continuïteit | E27: x | F27: x | G27: Tijdens audits wordt documentatie beschikbaar gesteld
A28: Medegebruikers panden
C36: Categorie | D36: Interpretatie
C37: Zeer hoog | D37: Het is essentieel voor de organisatie om aan eisen en verwachtingen van deze betrokkene te voldoen, en de belanghebbende sterk hecht aan informatiebeveiliging.
C38: Hoog | D38: Het is belangrijk voor de organisatie om aan eisen en verwachtingen van deze betrokkene te voldoen, en de betrokkene heeft belang aan informatiebeveiliging. Hieronder vallen ook vertegenwoordigers van belangrijke stakeholders.
C39: Matig | D39: Het is enigzins waardevol voor de organisatie om aan eisen en verwachtingen van deze betrokkene te voldoen, en de betrokkene heeft belang bij informatiebeveiliging.
C40: Laag | D40: Er zijn geen eisen afgesproken en de belanghebbende heeft geen concrete verwachtingen. Belanghebbende merkt weinig van eventuele incidenten of afwijkingen en wordt niet direct ontevreden

Sheet Assets
B1: Inventaris van informatiemiddelen
B2: Zie hieronder voor uitleg over categorieën
A3: Nr. | B3: Naam | C3: Bescrhijving | D3: Eigenaar | E3: Relevante VIB aspecten | F3: Is dit persoonlijke data? | G3: Wie moet toegang hebben? | H3: Categorie
A4: 1 | B4: Dashboard1 | C4: Dashboard met wekelijkse rapportages voor de financiële afdeling | D4: CFO | E4: VIB | F4: nee | G4: Alle ontwikkelaarsrollen | H4: Data
A5: 2 | B5: CRM systeem | C5: Systeem van salesforce met data van alle retailklanten | D5: Sales | E5: VI | F5: ja | G5: Verkoopmanagers | H5: Derden
A6: 3 | B6: Dashboard1 broncode | C6: Rapportscripts voor het maken van dashboard1 | D6: CFO | E6: VIB | F6: nee | G6: Ontwikkelaars | H6: Software
A7: 4 | B7: Confluence | C7: Documentatie op Confluence | D7: CTO | E7: VI | F7: ja | G7: Eigen toegangsbeheer | H7: Organisatie
A8: 5 | B8: Gebruikers data | C8: Gebruiker uploads | E8: .
A9: 6 | B9: Web Apps | C9: Web applicaties | E9: .
A10: 7 | B10: Websites | C10: Openbare websites | E10: .
A11: 8 | B11: Laptops | C11: Laptops van medewerkers | E11: .
A12: 9 | B12: Servers | C12: Servers (in de cloud, meestal AWS) | E12: .
A13: 10 | B13: Telefoons | C13: Mobiele telefoons | E13: .
A14: 11 | B14: HR | C14: HR-bestanden | E14: .
A15: 12 | B15: Financiën | C15: Financiën en accounting | E15: .
A16: 13 | B16: Bankrekening | C16: Bankrekening bedrijf | E16: .
A17: 14 | B17: Documentatie | C17: Slack / Wiki / Confluence | E17: .
A18: 15 | B18: Logs | C18: Logbestanden (toegangslogboek, foutenlogboek) | E18: .
A19: 16 | B19: Hoofdkantoor | C19: Hoofdkantoor kamer | E19: .
A20: 17 | B20: Cloud opslag | C20: Dropbox / Drive / Onedrive | E20: .
A21: 18 | E21: .
A22: 19 | E22: .
A23: 20 | E23: .
A24: 21 | E24: .
A25: 22 | E25: .
A26: 23 | E26: .
A27: 24 | E27: .
A28: 25 | E28: .
A29: 26 | E29: .
A30: 27 | E30: .
A31: 28 | E31: .
A32: 29 | E32: .
... A53: 50 | E53: .
B57: Categorie | C57: Beschrijving | F57: Klasse waarden | G57: Klasse waarden
B58: Mensen | C58: Informatie toegankelijk voor één persoon of gekoppeld aan unieke rol | F58: VIB | G58: ja
B59: Apparatuur | C59: Informatie binnenin of gegenereerd op/door specifieke apparaten | F59: VI | G59: nee
B60: Omgeving | C60: Informatie gekoppeld aan factoren buiten het bedrijf, b.v. stad, regio | F60: IB | G60: .
B61: Software | C61: Informatie opgeslagen door afzonderlijke IT-systemen | F61: none
B62: Gegevens | C62: Gestructureerde informatie niet gekoppeld aan één softwaresysteem | F62: .
B63: Organisatie | C63: Alle informatie over de organisatie, b.v. organisatiestructuur, processen
...

Sheet Risicoregister2026
B1: Risico's en controles 2024
B2: Versie: 0.1
B3: Datum (laatste update): 02/04/2023
B4: Classificatie: intern gebruik
B5: *VIB = Vertrouwelijkheid, Integriteit, Beschikbaarheid | G5: Met huidige maatregelen/controles | N5: Na aanvullende maatregelen/controles
A6: Nr. | B6: Evenement | C6: VIB | D6: Bron van risico | E6: Toepasselijke SoA-controles/maatregelen | F6: Aanvullende maatregelen genomen | G6: Waarschijnlijkheid | H6: Impact | I6: Risk score | J6: Behandelingsbeslissing (Accepteren, Verminderen) | K6: Risicobehandelplan in 2026 | L6: Naam risico-eigenaar | M6: Datum goedkeuring risico-eigenaar | N6: Waarschijnlijkheid | O6: Impact | P6: Risico score
A7: 1 | B7: Inbreuk op wet- of regelgeving inzake informatiebescherming | C7: VIB | D7: Risicosessie 01-01-2023 | E7: 5.5, 5.31, 5.34, 8.10, 8.11 | F7: … | G7: Medium | H7: Hoog | I7: =VLOOKUP(G7,$I$50:$M$54,5,FALSE)*VLOOKUP(H7,$I$50:$M$54,5,FALSE) -> 6 | J7: Verminderen | K7: … | L7: John Wick | M7: 44927 | N7: Medium | O7: Laag | P7: =VLOOKUP(N7,$I$50:$M$54,5,FALSE)*VLOOKUP(O7,$I$50:$M$54,5,FALSE) -> 2
A8: 2 | B8: Schending van de contractuele verplichting tot informatiebescherming | C8: VIB | D8: Risicosessie 01-01-2023 | E8: 5.31, | F8: … | G8: Medium | H8: Hoog | I8: =VLOOKUP(G8,$I$50:$M$54,5,FALSE)*VLOOKUP(H8,$I$50:$M$54,5,FALSE) -> 6 | J8: Verminderen | K8: … | L8: John Wick | M8: 44927 | N8: Medium | O8: Laag | P8: =VLOOKUP(N8,$I$50:$M$54,5,FALSE)*VLOOKUP(O8,$I$50:$M$54,5,FALSE) -> 2
A9: 3 | B9: Verlies van activa door werknemers | C9: VIB | D9: Risicosessie 01-01-2023 | E9: 5.9, 5.10, 8.1, | F9: … | G9: Medium | H9: Hoog | I9: =VLOOKUP(G9,$I$50:$M$54,5,FALSE)*VLOOKUP(H9,$I$50:$M$54,5,FALSE) -> 6 | J9: Verminderen | K9: … | L9: John Wick | M9: 44927 | N9: Medium | O9: Laag | P9: =VLOOKUP(N9,$I$50:$M$54,5,FALSE)*VLOOKUP(O9,$I$50:$M$54,5,FALSE) -> 2
A10: 4 | B10: Onjuiste omgang met informatiemiddelen door werknemers | C10: VIB | D10: Risicosessie 01-01-2023 | E10: 5.36, 5.37, 6.7, 7.13, 7.14 | F10: … | G10: Medium | H10: Hoog | I10: =VLOOKUP(G10,$I$50:$M$54,5,FALSE)*VLOOKUP(H10,$I$50:$M$54,5,FALSE) -> 6 | J10: Verminderen | K10: … | L10: John Wick | M10: 44927 | N10: Medium | O10: Laag | P10: =VLOOKUP(N10,$I$50:$M$54,5,FALSE)*VLOOKUP(O10,$I$50:$M$54,5,FALSE) -> 2
A11: 5 | B11: CIA van informatie gecompromitteerd door werknemer per ongeluk | C11: VIB | D11: Risicosessie 01-01-2023 | E11: 6.2, 6.3 | F11: … | G11: Medium | H11: Hoog | I11: =VLOOKUP(G11,$I$50:$M$54,5,FALSE)*VLOOKUP(H11,$I$50:$M$54,5,FALSE) -> 6 | J11: Verminderen | K11: … | L11: John Wick | M11: 44927 | N11: Medium | O11: Laag | P11: =VLOOKUP(N11,$I$50:$M$54,5,FALSE)*VLOOKUP(O11,$I$50:$M$54,5,FALSE) -> 2
A12: 6 | B12: CIA van informatie die met opzet is gecompromitteerd door (ex-)medewerker | C12: VIB | D12: Risicosessie 01-01-2023 | E12: 6.1, 6.2, 6.4, 6.5, 6.6, 8.12 | F12: … | G12: Medium | H12: Hoog | I12: =VLOOKUP(G12,$I$50:$M$54,5,FALSE)*VLOOKUP(H12,$I$50:$M$54,5,FALSE) -> 6 | J12: Verminderen | K12: … | L12: John Wick | M12: 44927 | N12: Medium | O12: Laag | P12: =VLOOKUP(N12,$I$50:$M$54,5,FALSE)*VLOOKUP(O12,$I$50:$M$54,5,FALSE) -> 2
A13: 7 | B13: Informatie gecompromitteerd vanwege fysieke toegang tot bedrijfsmiddelen | C13: VIB | D13: Risicosessie 01-01-2023 | E13: 7.1, 7.2, 7.3, 7.4, 7.6, 7.7, 7.8, 7.9, 7.10 | F13: … | G13: Medium | H13: Hoog | I13: =VLOOKUP(G13,$I$50:$M$54,5,FALSE)*VLOOKUP(H13,$I$50:$M$54,5,FALSE) -> 6 | J13: Verminderen | K13: … | L13: John Wick | M13: 44927 | N13: Medium | O13: Laag | P13: =VLOOKUP(N13,$I$50:$M$54,5,FALSE)*VLOOKUP(O13,$I$50:$M$54,5,FALSE) -> 2
A14: 8 | B14: Malware op interne systemen | C14: VIB | D14: Risicosessie 01-01-2023 | E14: 8.7, 8.18 | F14: … | G14: Medium | H14: Hoog | I14: =VLOOKUP(G14,$I$50:$M$54,5,FALSE)*VLOOKUP(H14,$I$50:$M$54,5,FALSE) -> 6 | J14: Verminderen | K14: … | L14: John Wick | M14: 44927 | N14: Medium | O14: Laag | P14: =VLOOKUP(N14,$I$50:$M$54,5,FALSE)*VLOOKUP(O14,$I$50:$M$54,5,FALSE) -> 2
A15: 9 | B15: Ongeoorloofde toegang tot interne netwerken | C15: VI | D15: Risicosessie 01-01-2023 | E15: 8.20, 8.21, 8.22 | F15: … | G15: Medium | H15: Hoog | I15: =VLOOKUP(G15,$I$50:$M$54,5,FALSE)*VLOOKUP(H15,$I$50:$M$54,5,FALSE) -> 6 | J15: Verminderen | K15: … | L15: John Wick | M15: 44927 | N15: Medium | O15: Laag | P15: =VLOOKUP(N15,$I$50:$M$54,5,FALSE)*VLOOKUP(O15,$I$50:$M$54,5,FALSE) -> 2
A16: 10 | B16: CIA van de broncode is gecompromitteerd | C16: VIB | D16: Risicosessie 01-01-2023 | E16: 8.4, | F16: … | G16: Medium | H16: Hoog | I16: =VLOOKUP(G16,$I$50:$M$54,5,FALSE)*VLOOKUP(H16,$I$50:$M$54,5,FALSE) -> 6 | J16: Verminderen | K16: … | L16: John Wick | M16: 44927 | N16: Medium | O16: Laag | P16: =VLOOKUP(N16,$I$50:$M$54,5,FALSE)*VLOOKUP(O16,$I$50:$M$54,5,FALSE) -> 2
A17: 11 | B17: Verkeerde configuratie van het IT-systeem leidt tot kwetsbaarheid | C17: VI | D17: Risicosessie 01-01-2023 | E17: 8.9, 8.19 | F17: … | G17: Medium | H17: Hoog | I17: =VLOOKUP(G17,$I$50:$M$54,5,FALSE)*VLOOKUP(H17,$I$50:$M$54,5,FALSE) -> 6 | J17: Verminderen | K17: … | L17: John Wick | M17: 44927 | N17: Medium | O17: Laag | P17: =VLOOKUP(N17,$I$50:$M$54,5,FALSE)*VLOOKUP(O17,$I$50:$M$54,5,FALSE) -> 2
A18: 12 | B18: Ongeoorloofde toegang tot informatie door personeel | C18: VI | D18: Risicosessie 01-01-2023 | E18: 5.12, 5.13, 5.15, 5.16, 5.17, 5.18, 8.3, 8.5 | F18: … | G18: Medium | H18: Hoog | I18: =VLOOKUP(G18,$I$50:$M$54,5,FALSE)*VLOOKUP(H18,$I$50:$M$54,5,FALSE) -> 6 | J18: Verminderen | K18: … | L18: John Wick | M18: 44927 | N18: Medium | O18: Laag | P18: =VLOOKUP(N18,$I$50:$M$54,5,FALSE)*VLOOKUP(O18,$I$50:$M$54,5,FALSE) -> 2
... A30: 24 | B30: Wijziging in infrastructuur of configuratie leidt tot nieuwe kwetsbaarheid | C30: VI | D30: Risicosessie 01-01-2023 | E30: 5.8, 8.32 | F30: … | G30: Medium | H30: Hoog | I30: =VLOOKUP(G30,$I$50:$M$54,5,FALSE)*VLOOKUP(H30,$I$50:$M$54,5,FALSE) -> 6 | J30: Verminderen | K30: … | L30: John Wick | M30: 44927 | N30: Medium | O30: Laag | P30: =VLOOKUP(N30,$I$50:$M$54,5,FALSE)*VLOOKUP(O30,$I$50:$M$54,5,FALSE) -> 2
A31: 25 | B31: Audits of inspecties verstoren de bedrijfsvoering | C31: IB | D31: Risicosessie 01-01-2023 | E31: 8.34 | F31: … | G31: Medium | H31: Hoog | I31: =VLOOKUP(G31,$I$50:$M$54,5,FALSE)*VLOOKUP(H31,$I$50:$M$54,5,FALSE) -> 6 | J31: Verminderen | K31: … | L31: John Wick | M31: 44927 | N31: Medium | O31: Laag | P31: =VLOOKUP(N31,$I$50:$M$54,5,FALSE)*VLOOKUP(O31,$I$50:$M$54,5,FALSE) -> 2
A32: 26 | B32: Onopzettelijke wijzigingen in de productieomgeving | C32: IB | D32: Risicosessie 01-01-2023 | E32: 8.31, | F32: … | G32: Medium | H32: Hoog | I32: =VLOOKUP(G32,$I$50:$M$54,5,FALSE)*VLOOKUP(H32,$I$50:$M$54,5,FALSE) -> 6 | J32: Verminderen | K32: … | L32: John Wick | M32: 44927 | N32: Medium | O32: Laag | P32: =VLOOKUP(N32,$I$50:$M$54,5,FALSE)*VLOOKUP(O32,$I$50:$M$54,5,FALSE) -> 2
A33: 27 | B33: Door derden ontwikkelde software bevat een kwetsbaarheid | C33: VI | D33: Risicosessie 01-01-2023 | E33: 8.26, 8.30 | F33: … | G33: Medium | H33: Hoog | I33: =VLOOKUP(G33,$I$50:$M$54,5,FALSE)*VLOOKUP(H33,$I$50:$M$54,5,FALSE) -> 6 | J33: Verminderen | K33: … | L33: John Wick | M33: 44927 | N33: Medium | O33: Laag | P33: =VLOOKUP(N33,$I$50:$M$54,5,FALSE)*VLOOKUP(O33,$I$50:$M$54,5,FALSE) -> 2
A34: 28 | B34: Medewerker bezoekt website met bekende malware | C34: VI | D34: Risicosessie 01-01-2023 | E34: 8.23, | F34: … | G34: Medium | H34: Hoog | I34: =VLOOKUP(G34,$I$50:$M$54,5,FALSE)*VLOOKUP(H34,$I$50:$M$54,5,FALSE) -> 6 | J34: Verminderen | K34: … | L34: John Wick | M34: 44927 | N34: Medium | O34: Laag | P34: =VLOOKUP(N34,$I$50:$M$54,5,FALSE)*VLOOKUP(O34,$I$50:$M$54,5,FALSE) -> 2
A35: 29 | B35: Openbaarmaking van informatie of wijzigingen tijdens het transport | C35: VI | D35: Risicosessie 01-01-2023 | E35: 5.14, 7.12, 8.24 | F35: … | G35: Medium | H35: Hoog | I35: =VLOOKUP(G35,$I$50:$M$54,5,FALSE)*VLOOKUP(H35,$I$50:$M$54,5,FALSE) -> 6 | J35: Verminderen | K35: … | L35: John Wick | M35: 44927 | N35: Medium | O35: Laag | P35: =VLOOKUP(N35,$I$50:$M$54,5,FALSE)*VLOOKUP(O35,$I$50:$M$54,5,FALSE) -> 2
A36: 30 | B36: Misbruik van beheerderstoegang | C36: VIB | D36: Risicosessie 01-01-2023 | E36: 5.3, 8.2, | F36: … | G36: Medium | H36: Hoog | I36: =VLOOKUP(G36,$I$50:$M$54,5,FALSE)*VLOOKUP(H36,$I$50:$M$54,5,FALSE) -> 6 | J36: Verminderen | K36: … | L36: John Wick | M36: 44927 | N36: Medium | O36: Laag | P36: =VLOOKUP(N36,$I$50:$M$54,5,FALSE)*VLOOKUP(O36,$I$50:$M$54,5,FALSE) -> 2
A37: 31 | B37: IT-systemen vallen uit door overcapaciteit | C37: IB | D37: Risicosessie 01-01-2023 | E37: 8.6, | F37: … | G37: Medium | H37: Hoog | I37: =VLOOKUP(G37,$I$50:$M$54,5,FALSE)*VLOOKUP(H37,$I$50:$M$54,5,FALSE) -> 6 | J37: Verminderen | K37: … | L37: John Wick | M37: 44927 | N37: Medium | O37: Laag | P37: =VLOOKUP(N37,$I$50:$M$54,5,FALSE)*VLOOKUP(O37,$I$50:$M$54,5,FALSE) -> 2
A38: 32 | B38: Beveiliging van cloudleverancier is een blinde vlek | C38: VIB | D38: Risicosessie 01-01-2023 | E38: 5.23, | F38: … | G38: Medium | H38: Hoog | I38: =VLOOKUP(G38,$I$50:$M$54,5,FALSE)*VLOOKUP(H38,$I$50:$M$54,5,FALSE) -> 6 | J38: Verminderen | K38: … | L38: John Wick | M38: 44927 | N38: Medium | O38: Laag | P38: =VLOOKUP(N38,$I$50:$M$54,5,FALSE)*VLOOKUP(O38,$I$50:$M$54,5,FALSE) -> 2
A39: 33 | B39: Managers nemen hun verantwoordelijkheid voor informatiebeveiliging niet | C39: VIB | D39: Risicosessie 01-01-2023 | E39: 5.1, 5.2, 5.4 | F39: … | G39: Medium | H39: Hoog | I39: =VLOOKUP(G39,$I$50:$M$54,5,FALSE)*VLOOKUP(H39,$I$50:$M$54,5,FALSE) -> 6 | J39: Verminderen | K39: … | L39: John Wick | M39: 44927 | N39: Medium | O39: Laag | P39: =VLOOKUP(N39,$I$50:$M$54,5,FALSE)*VLOOKUP(O39,$I$50:$M$54,5,FALSE) -> 2
A40: 34 | B40: Nieuw1 | C40: VI | D40: Kickoff? | E40: n/a | G40: Laag | H40: Laag | I40: =VLOOKUP(G40,$I$50:$M$54,5,FALSE)*VLOOKUP(H40,$I$50:$M$54,5,FALSE) -> 1 | J40: Aanvaarden | K40: n/a | L40: John Wick | M40: 45292 | N40: Laag | O40: Laag | P40: =VLOOKUP(N40,$I$50:$M$54,5,FALSE)*VLOOKUP(O40,$I$50:$M$54,5,FALSE) -> 1
A41: 35 | B41: Nieuw2 | C41: VI | D41: Kickoff? | E41: n/a | F41: … | G41: Laag | H41: Laag | I41: =VLOOKUP(G41,$I$50:$M$54,5,FALSE)*VLOOKUP(H41,$I$50:$M$54,5,FALSE) -> 1 | J41: Aanvaarden | K41: … | L41: John Wick | M41: 45292 | N41: Laag | O41: Laag | P41: =VLOOKUP(N41,$I$50:$M$54,5,FALSE)*VLOOKUP(O41,$I$50:$M$54,5,FALSE) -> 1
A42: 36 | B42: Nieuw3 | C42: VI | D42: Kickoff? | E42: n/a | F42: … | G42: Laag | H42: Laag | I42: =VLOOKUP(G42,$I$50:$M$54,5,FALSE)*VLOOKUP(H42,$I$50:$M$54,5,FALSE) -> 1 | J42: Aanvaarden | K42: … | L42: John Wick | M42: 45292 | N42: Laag | O42: Laag | P42: =VLOOKUP(N42,$I$50:$M$54,5,FALSE)*VLOOKUP(O42,$I$50:$M$54,5,FALSE) -> 1
A43: 37 | B43: Nieuw4 | C43: VI | D43: Kickoff? | E43: n/a | F43: … | G43: Laag | H43: Laag | I43: =VLOOKUP(G43,$I$50:$M$54,5,FALSE)*VLOOKUP(H43,$I$50:$M$54,5,FALSE) -> 1 | J43: Aanvaarden | K43: … | L43: John Wick | M43: 45292 | N43: Laag | O43: Laag | P43: =VLOOKUP(N43,$I$50:$M$54,5,FALSE)*VLOOKUP(O43,$I$50:$M$54,5,FALSE) -> 1
A44: 38 | B44: Nieuw5 | C44: VI | D44: Kickoff? | E44: n/a | F44: … | G44: Laag | H44: Laag | I44: =VLOOKUP(G44,$I$50:$M$54,5,FALSE)*VLOOKUP(H44,$I$50:$M$54,5,FALSE) -> 1 | J44: Aanvaarden | K44: … | L44: John Wick | M44: 45292 | N44: Laag | O44: Laag | P44: =VLOOKUP(N44,$I$50:$M$54,5,FALSE)*VLOOKUP(O44,$I$50:$M$54,5,FALSE) -> 1
A45: 39 | B45: Nieuw6 | C45: VI | D45: Kickoff? | E45: n/a | F45: … | G45: Laag | H45: Laag | I45: =VLOOKUP(G45,$I$50:$M$54,5,FALSE)*VLOOKUP(H45,$I$50:$M$54,5,FALSE) -> 1 | J45: Aanvaarden | K45: … | L45: John Wick | M45: 45292 | N45: Laag | O45: Laag | P45: =VLOOKUP(N45,$I$50:$M$54,5,FALSE)*VLOOKUP(O45,$I$50:$M$54,5,FALSE) -> 1
I49: Categorie | J49: Waarschijnlijkheid / year | K49: Impact | M49: Score
I50: Hoog | J50: >30% | K50: > € 100.000, of levens/organisatie in gevaar | M50: 3
I51: Medium | J51: >10% | K51: > € 10.000, primair proces verstoord voor >8h | M51: 2
I52: Laag | J52: <10% | K52: < € 10.000, secundair proces verstoord | M52: 1
I53: . | M53: 0
I54: None | J54: <1% | K54: < € 500, processen niet zichtbaar verstoord | M54: 0

Sheet Vvt-check
B1: Dit tabblad helpt u te controleren of u alle SoA-controles in overweging hebt genomen tijdens uw risicobeoordelingen
B2: *Handmatig tellen 5.1, 5.2, 5.3, 7.1, 8.1, 8.2, 8.3
B4: ISO 27001 control | C4: Tijd in risico's
A5: 5.1, | B5: Beleid voor informatiebeveiliging | C5: =COUNTIF(Risicoregister2026!$E$7:$E$39,"*"&A5&"*")+COUNTIF(Risicoregister2026!$E$7:$E$39,A5) -> 1 | E5: =A5
A6: 5.2, | B6: Rollen en verantwoordelijkheden op het gebied van informatiebeveiliging | C6: =COUNTIF(Risicoregister2026!$E$7:$E$39,"*"&A6&"*")+COUNTIF(Risicoregister2026!$E$7:$E$39,A6) -> 1
A7: 5.3, | B7: Scheiding van taken | C7: =COUNTIF(Risicoregister2026!$E$7:$E$39,"*"&A7&"*")+COUNTIF(Risicoregister2026!$E$7:$E$39,A7) -> 1
A8: 5.4 | B8: Directie verantwoordelijkheden | C8: =COUNTIF(Risicoregister2026!$E$7:$E$39,"*"&A8&"*")+COUNTIF(Risicoregister2026!$E$7:$E$39,A8) -> 1
A9: 5.5 | B9: Contact met autoriteiten | C9: =COUNTIF(Risicoregister2026!$E$7:$E$39,"*"&A9&"*")+COUNTIF(Risicoregister2026!$E$7:$E$39,A9) -> 1
A10: 5.6 | B10: Contact met speciale belangengroepen | C10: =COUNTIF(Risicoregister2026!$E$7:$E$39,"*"&A10&"*")+COUNTIF(Risicoregister2026!$E$7:$E$39,A10) -> 1
A11: 5.7 | B11: Bedreigingsinformatie | C11: =COUNTIF(Risicoregister2026!$E$7:$E$39,"*"&A11&"*")+COUNTIF(Risicoregister2026!$E$7:$E$39,A11) -> 1
A12: 5.8 | B12: Informatiebeveiliging in projectmanagement | C12: =COUNTIF(Risicoregister2026!$E$7:$E$39,"*"&A12&"*")+COUNTIF(Risicoregister2026!$E$7:$E$39,A12) -> 1
A13: 5.9 | B13: Inventarisatie van informatie en andere bijbehorende activa | C13: =COUNTIF(Risicoregister2026!$E$7:$E$39,"*"&A13&"*")+COUNTIF(Risicoregister2026!$E$7:$E$39,A13) -> 1
A14: 5.10 | B14: Aanvaardbaar gebruik van informatie en andere bijbehorende bedrijfsmiddelen | C14: =COUNTIF(Risicoregister2026!$E$7:$E$39,"*"&A14&"*")+COUNTIF(Risicoregister2026!$E$7:$E$39,A14) -> 1
A15: 5.11 | B15: Teruggave van activa | C15: =COUNTIF(Risicoregister2026!$E$7:$E$39,"*"&A15&"*")+COUNTIF(Risicoregister2026!$E$7:$E$39,A15) -> 1
A16: 5.12 | B16: Classificatie van informatie | C16: =COUNTIF(Risicoregister2026!$E$7:$E$39,"*"&A16&"*")+COUNTIF(Risicoregister2026!$E$7:$E$39,A16) -> 1
A17: 5.13 | B17: Etikettering van informatie | C17: =COUNTIF(Risicoregister2026!$E$7:$E$39,"*"&A17&"*")+COUNTIF(Risicoregister2026!$E$7:$E$39,A17) -> 1
... A97: 8.34 | B97: Bescherming van informatiesystemen tijdens audittesten | C97: =COUNTIF(Risicoregister2026!$E$7:$E$39,"*"&A97&"*")+COUNTIF(Risicoregister2026!$E$7:$E$39,A97) -> 0

Sheet VvT-print
A1: Verklaring van Toepasselijkheid
A2: Organisatie:
A3: Versie | B3: 1.0
A4: datum | B4: 45447
A5: Classificatie: | B5: Openbaar
A6: Norm: | B6: NEN-ISO 27001-2023-NL
A8: Nr. | B8: Hoofdstuk | C8: Onderwerp | D8: Beheersmaatregel | E8: Van toepassing | F8: Motivatie voor toepassen | G8: Motivatie voor niet toepassen | H8: Geïmplementeerd in organisatie
E9: (Ja/Nee) | H9: (Ja/Nee)
A10: 5.1 | B10: Organisatorische beheersmaatregelen | C10: Beleidsregels voor informatiebeveiliging | D10: Informatiebeveiligingsbeleid en onderwerpspecifieke beleidsregels moeten worden gedefinieerd, goedgekeurd door het management, gepubliceerd, gecommuniceerd aan en erkend door relevant personeel en relevante belanghebbenden en met geplande tussenpozen of zodra zich belangrijke veranderingen voordoen, te worden beoordeeld. | E10: Ja | F10: Risicoanalyse | H10: Ja
A11: 5.2 | B11: Organisatorische beheersmaatregelen | C11: Rollen en verantwoordelijkheden bij informatiebeveiliging | D11: Rollen en verantwoordelijkheden bij informatiebeveiliging moeten worden gedefinieerd en toegewezen overeenkomstig de behoeften van de organisatie. | E11: Ja | F11: Risicoanalyse | H11: Ja
A12: 5.3 | B12: Organisatorische beheersmaatregelen | C12: Functiescheiding | D12: Conflicterende taken en conflicterende verantwoordelijkheden moeten worden gescheiden. | E12: Ja | F12: Risicoanalyse | H12: Ja
A13: 5.4 | B13: Organisatorische beheersmaatregelen | C13: Managementverantwoordelijkheden | D13: Het management moet van al het personeel eisen dat ze informatiebeveiliging toepassen overeenkomstig het vastgestelde informatiebeveiligingsbeleid, de onderwerpspecifieke beleidsregels en procedures van de organisatie. | E13: Ja | F13: Risicoanalyse | H13: Ja
A14: 5.5 | B14: Organisatorische beheersmaatregelen | C14: Contact met overheidsinstanties | D14: De organisatie moet contact met de relevante instanties leggen en onderhouden. | E14: Ja | F14: Risicoanalyse | H14: Ja
A15: 5.6 | B15: Organisatorische beheersmaatregelen | C15: Contact met speciale belangengroepen | D15: De organisatie moet contacten met speciale belangengroepen of andere gespecialiseerde beveiligingsfora en beroepsverenigingen leggen en onderhouden. | E15: Ja | F15: Risicoanalyse | H15: Ja
A16: 5.7 | B16: Organisatorische beheersmaatregelen | C16: Informatie en analyses over dreigingen | D16: Informatie met betrekking tot informatiebeveiligingsdreigingen moet worden verzameld en geanalyseerd om informatie en analyses over dreigingen te produceren. | E16: Ja | F16: Risicoanalyse | H16: Ja
A17: 5.8 | B17: Organisatorische beheersmaatregelen | C17: Informatiebeveiliging in projectmanagement | D17: Informatiebeveiliging moet worden geïntegreerd in projectmanagement. | E17: Ja | F17: Risicoanalyse | H17: Ja
A18: 5.9 | B18: Organisatorische beheersmaatregelen | C18: Inventarisatie van informatie en andere gerelateerde bedrijfsmiddelen | D18: Er moet een inventarislijst van informatie en andere gerelateerde bedrijfsmiddelen, met inbegrip van de eigenaren, worden opgesteld en onderhouden. | E18: Ja | F18: Risicoanalyse | H18: Ja
A19: 5.10 | B19: Organisatorische beheersmaatregelen | C19: Aanvaardbaar gebruik van informatie en andere gerelateerde bedrijfsmiddelen | D19: Regels voor het aanvaardbaar gebruik van en procedures voor het omgaan met informatie en andere gerelateerde bedrijfsmiddelen moeten worden vastgesteld, gedocumenteerd en geïmplementeerd. | E19: Ja | F19: Risicoanalyse | H19: Ja
A20: 5.11 | B20: Organisatorische beheersmaatregelen | C20: Retourneren van bedrijfsmiddelen | D20: Personeel en andere belanghebbenden, al naargelang de situatie, moeten alle bedrijfsmiddelen van de organisatie die ze in hun bezit hebben bij beëindiging van hun dienstverband, contract of overeenkomst retourneren. | E20: Ja | F20: Risicoanalyse | H20: Ja
A21: 5.12 | B21: Organisatorische beheersmaatregelen | C21: Classificeren van informatie | D21: Informatie moet worden geclassificeerd volgens de informatiebeveiligingsbehoeften van de organisatie, op basis van de eisen voor vertrouwelijkheid, integriteit, beschikbaarheid en relevante belanghebbenden. | E21: Ja | F21: Risicoanalyse | H21: Ja
A22: 5.13 | B22: Organisatorische beheersmaatregelen | C22: Labelen van informatie | D22: Om informatie te labelen moet een passende reeks procedures worden vastgesteld en geïmplementeerd in overeenstemming met het informatieclassificatieschema dat is vastgesteld door de organisatie. | E22: Ja | F22: Risicoanalyse | H22: Ja
A23: 5.14 | B23: Organisatorische beheersmaatregelen | C23: Overdragen van informatie | D23: Er moeten regels, procedures of overeenkomsten voor informatieoverdracht zijn vastgesteld voor alle soorten van overdracht binnen de organisatie en tussen de organisatie en andere partijen. | E23: Ja | F23: Risicoanalyse | H23: Ja
A24: 5.15 | B24: Organisatorische beheersmaatregelen | C24: Toegangsbeveiliging | D24: Er moeten regels op basis van bedrijfs- en informatiebeveiligingseisen te worden vastgesteld en geïmplementeerd om de fysieke en logische toegang tot informatie en andere gerelateerde bedrijfsmiddelen te beheersen. | E24: Ja | F24: Risicoanalyse | H24: Ja
A25: 5.16 | B25: Organisatorische beheersmaatregelen | C25: Identiteitsbeheer | D25: De volledige levenscyclus van identiteiten moet worden beheerd. | E25: Ja | F25: Risicoanalyse | H25: Ja
A26: 5.17 | B26: Organisatorische beheersmaatregelen | C26: Beheren van authenticatie-informatie | D26: De toewijzing en het beheer van authenticatie-informatie moet worden beheerst door middel van een beheerproces waarvan het informeren van het personeel over de juiste manier van omgaan met authenticatie-informatie deel uitmaakt. | E26: Ja | F26: Risicoanalyse | H26: Ja
A27: 5.18 | B27: Organisatorische beheersmaatregelen | C27: Toegangsrechten | D27: Toegangsrechten met betrekking tot informatie en andere gerelateerde bedrijfsmiddelen moeten worden verstrekt, beoordeeld, aangepast en verwijderd overeenkomstig het onderwerpspecifieke beleid en de regels inzake toegangsbeveiliging van de organisatie. | E27: Ja | F27: Risicoanalyse | H27: Ja
A28: 5.19 | B28: Organisatorische beheersmaatregelen | C28: Informatiebeveiliging in leveranciersrelaties | D28: Er moeten processen en procedures worden vastgesteld en geïmplementeerd om de informatiebeveiligingsrisico’s in verband met het gebruik van producten of diensten van de leverancier te beheren. | E28: Ja | F28: Risicoanalyse | H28: Ja
A29: 5.20 | B29: Organisatorische beheersmaatregelen | C29: Adresseren van informatiebeveiliging in leveranciersovereenkomsten | D29: Relevante informatiebeveiligingseisen moeten worden vastgesteld en met elke leverancier op basis van het type leveranciersrelatie te worden overeengekomen. | E29: Ja | F29: Risicoanalyse | H29: Ja
A30: 5.21 | B30: Organisatorische beheersmaatregelen | C30: Beheren van informatiebeveiliging in de ICT-keten | D30: Er moeten processen en procedures worden vastgesteld en geïmplementeerd om de informatiebeveiligingsrisico’s in verband met de toeleveringsketen van ICT-producten en -diensten te beheren. | E30: Ja | F30: Risicoanalyse | H30: Ja
A31: 5.22 | B31: Organisatorische beheersmaatregelen | C31: Monitoren, beoordelen en het beheren van wijzigingen van leveranciersdiensten | D31: De organisatie moet de informatiebeveiligingspraktijken en de leveranciersdiensten regelmatig te monitoren, beoordelen, evalueren en veranderingen daaraan te beheren. | E31: Ja | F31: Risicoanalyse | H31: Ja
A32: 5.23 | B32: Organisatorische beheersmaatregelen | C32: Informatiebeveiliging voor het gebruik van clouddiensten | D32: Processen voor het aanschaffen, gebruiken, beheren en beëindigen van clouddiensten moeten overeenkomstig de informatiebeveiligingseisen van de organisatie worden opgesteld. | E32: Ja | F32: Risicoanalyse | H32: Ja
A33: 5.24 | B33: Organisatorische beheersmaatregelen | C33: Plannen en voorbereiden van het beheer van informatiebeveiligingsincidenten | D33: De organisatie moet plannen op te stellen voor en zich voorbereiden op het beheren van informatiebeveiliging-sincidenten door processen, rollen en verantwoordelijkheden voor het beheer van informatiebeveiligingsincidenten te definiëren, vast te stellen en te communiceren. | E33: Ja | F33: Risicoanalyse | H33: Ja
A34: 5.25 | B34: Organisatorische beheersmaatregelen | C34: Beoordelen van en besluiten over informatiebeveiligingsgebeurtenissen | D34: De organisatie moet informatiebeveiligingsgebeurtenissen te beoordelen en te beslissen of ze moeten worden gecategoriseerd als informatiebeveiligingsincidenten. | E34: Ja | F34: Risicoanalyse | H34: Ja
A35: 5.26 | B35: Organisatorische beheersmaatregelen | C35: Reageren op informatiebeveiligingsincidenten | D35: Op informatiebeveiligingsincidenten moet worden gereageerd in overeenstemming met de gedocumenteerde procedures. | E35: Ja | F35: Risicoanalyse | H35: Ja
A36: 5.27 | B36: Organisatorische beheersmaatregelen | C36: Leren van informatiebeveiligingsincidenten | D36: Kennis die is opgedaan met informatiebeveiligingsincidenten moet worden gebruikt om de beheersmaatregelen voor informatiebeveiliging te versterken en te verbeteren. | E36: Ja | F36: Risicoanalyse | H36: Ja
A37: 5.28 | B37: Organisatorische beheersmaatregelen | C37: Verzamelen van bewijsmateriaal | D37: De organisatie moet procedures vast stellen en implementeren voor het identificeren, verzamelen, verkrijgen en bewaren van bewijs met betrekking tot informatiebeveiligingsgebeurtenissen. | E37: Ja | F37: Risicoanalyse | H37: Ja
A38: 5.29 | B38: Organisatorische beheersmaatregelen | C38: Informatiebeveiliging tijdens een verstoring | D38: De organisatie moet plannen maken voor het op het passende niveau waarborgen van de informatiebeveiliging tijdens een verstoring. | E38: Ja | F38: Risicoanalyse | H38: Ja
A39: 5.30 | B39: Organisatorische beheersmaatregelen | C39: ICT-gereedheid voor bedrijfscontinuïteit | D39: De ICT-gereedheid moet worden gepland, geïmplementeerd, onderhouden en getest op basis van bedrijfs-continuïteitsdoelstellingen en ICT-continuïteitseisen. | E39: Ja | F39: Risicoanalyse | H39: Ja
A40: 5.31 | B40: Organisatorische beheersmaatregelen | C40: Wettelijke, statutaire, regelgevende en contractuele eisen | D40: Eisen van wettelijke, statutaire, regelgevende en contractuele eisen die relevant zijn voor informatiebeveiliging en de aanpak van de organisatie om aan deze eisen te voldoen moeten worden vastgesteld, gedocumenteerd en actueel gehouden. | E40: Ja | F40: Risicoanalyse | H40: Ja
A41: 5.32 | B41: Organisatorische beheersmaatregelen | C41: Intellectuele-eigendomsrechten | D41: De organisatie moet passende procedures te implementeren om intellectuele eigendomsrechten te beschermen. | E41: Ja | F41: Risicoanalyse | H41: Ja
...

Sheet Toelichting
A1: Issues & Belanghebbendenanalyse
B2: ISO 27001:2022 hoofdstuk | C2: Dit template
B3: 4.1 Inzicht verkrijgen in de organisatie en haar context De organisatie moet externe en interne onderwerpen vaststellen die relevant zijn voor haar doelstelling en die haar vermogen beïnvloeden om het (de) beoogde resulta(a)t(en) van haar managementsysteem voor informatiebeveiliging te behalen. | C3: Interne en externe issues
B4: 4.2 Inzicht verkrijgen in de behoeften en verwachtingen van belanghebbenden De organisatie moet vaststellen:
B5: a) welke belanghebbenden relevant zijn voor het managementsysteem voor informatiebeveiliging; | C5: Belanghebbendenanalyse ISMS column A
B6: b) welke eisen van deze belanghebbenden relevant zijn voor informatiebeveiliging. | C6: Belanghebbendenanalyse ISMS column C
B7: c) which of these requirements will be addressed through the information security management system | C7: Belanghebbendenanalyse ISMS column C
B8: 7.4 Communicatie De organisatie moet de behoefte vaststellen aan interne en externe communicatie die relevant is voor het managementsysteem voor informatiebeveiliging, waaronder:
B9: a) waarover te communiceren; | C9: Belanghebbendenanalyse ISMS columns D E F
B10: b) wanneer te communiceren; | C10: Belanghebbendenanalyse ISMS columns D E F
B11: c) met wie te communiceren; | C11: Belanghebbendenanalyse ISMS columns D E F
B12: d) wie moet communiceren; en | C12: Belanghebbendenanalyse ISMS columns D E F
B13: e) volgens welke processen de communicatie moet plaatsvinden. | C13: Belanghebbendenanalyse ISMS columns D E F
A15: Risico management process:
A16: Wij volgende de onderstaande stappen voor ons jaarlijkse risico management proces: | I16: Categorie | J16: Kans / jaar | K16: Impact | L16: Score
I17: Hoog | J17: >30% | K17: > € 100.000, of levens/organisatie in gevaar | L17: 3
A18: 1. Er wordt voor elk jaar een nieuw tabblad gemaakt | I18: Middel | J18: >10% | K18: > € 10.000, primair proces verstoord >8h | L18: 2
A19: 2. Risico's, reeds genomen maatregelen en eerste score worden ingevuld. De eerste keer is geheel nieuw, in alle andere jaren wordt resultaat vorig jaar als basis gebruikt | I19: Laag | J19: <10% | K19: < € 10.000, secundair proces verstoord | L19: 1
A20: 3. Het risicoregister bestaat uit verschillende Excel-bladen. Bij de start van een nieuwe jaarcyclus (bijv. 2021), kopieert het security team het Excel-blad van het | I20: . | L20: 0
A21: voorgaande jaar (bijv. 2020). Het overzicht van het voorgaande jaar (bijv. 2020) blijft staan als archief en het gekopieerde Excel-blad wordt gebruikt als werkdocument | I21: Geen | J21: <0.1% | K21: < € 500, processen niet zichtbaar verstoord | L21: 0
A22: voor het nieuwe jaar (bijv. 2021). In dit nieuwe werkblad (met aangepaste naam), worden de stappen hieronder uitgevoerd.
A23: 4. Er wordt bijgewerkt welke maatregelen (inclusief beheersmaatregelen uit Bijlage A ) al genomen zijn
A24: 5. Daarna weegt de risico-eigenaar de kans en impact van een dreiging, op basis van de huidige status.
A25: 6. Als de bijgewerkte risicoscore boven de drempelwaarde voor acceptatie uitkomt, wordt een nieuw behandelplan vastgesteld.
A26: 7. Als de bijgewerkte risicoscore onder de drempelwaarde voor acceptatie uitkomt, kan de risico-eigenaar kiezen om (1) het restrisico te accepteren of (2) een nieuw
A27: behandelplan op te stellen om het risico nog verder te verminderen.
A28: 8. Indien de risico-eigenaar het restrisico niet wenst te accepteren, worden aanvullende plannen opgenomen
A29: 9. Het security team en risico-eigenaar spreken een datum af wanneer deze verbeteringen worden afgerond.
A30: 10. De datum van het overleg met de risico-eigenaar, wordt ingevuld als ‘datum akkoord behandelplan door risico-eigenaar’.
A31: 11. Risico-eigenaren zijn zelf verantwoordelijk voor de behandeling van risico’s, tenzij een andere verantwoordelijke voor een behandelplan is aangewezen in het register.
A32: 12. Het security team monitort de voortgang op de behandelplannen door bespreking in het security overleg.
A35: Voor meer informatie bezoek: | C35: Kans | D35: 3 | E35: =$D35*E$24 -> 0 | F35: =$D35*F$24 -> 0 | G35: =$D35*G$24 -> 0
A36: https://ictinstitute.nl/risk-management-method/ | D36: 2 | E36: =$D36*E$24 -> 0 | F36: =$D36*F$24 -> 0 | G36: =$D36*G$24 -> 0
A37: https://ictinstitute.nl/project-risk-management-fundamentals/ | D37: 1 | E37: =$D37*E$24 -> 0 | F37: =$D37*F$24 -> 0 | G37: =$D37*G$24 -> 0
A38: https://ictinstitute.nl/project-risk-management-thesis/ | E38: 1 | F38: 2 | G38: 3
A39: https://ictinstitute.nl/expertises/security/ | E39: Impact
D41: Grenswaarde acceptatie: | G41: 5
A42: ISO 27001:2023 hoofdstuk | B42: Dit template | D42: Voor alle risico's met een score hoger dan de drempelwaarde moet er een aanvullend behandelplan komen
A43: 6.1.1 Algemeen Bij het plannen voor het managementsysteem voor informatiebeveiliging moet de organisatie de in 4.1 genoemde onderwerpen en de in 4.2 genoemde eisen overwegen, en de risico’s en kansen vaststellen die moeten worden aangepakt om: a) te bewerkstelligen dat het managementsysteem voor informatiebeveiliging zijn beoogde resulta(a)t(en) behaalt; b) ongewenste effecten te voorkomen of te beperken; en c) continue verbetering te bereiken. | B43: Tab Risico's en Maatregelen Kolom D
A44: De organisatie moet:
...
